Traceback (most recent call last):
  File "/opt/anaconda3/envs/jupyterbook/lib/python3.10/site-packages/jupyter_cache/executors/utils.py", line 51, in single_nb_execution
    executenb(
  File "/opt/anaconda3/envs/jupyterbook/lib/python3.10/site-packages/nbclient/client.py", line 1204, in execute
    return NotebookClient(nb=nb, resources=resources, km=km, **kwargs).execute()
  File "/opt/anaconda3/envs/jupyterbook/lib/python3.10/site-packages/nbclient/util.py", line 84, in wrapped
    return just_run(coro(*args, **kwargs))
  File "/opt/anaconda3/envs/jupyterbook/lib/python3.10/site-packages/nbclient/util.py", line 62, in just_run
    return loop.run_until_complete(coro)
  File "/opt/anaconda3/envs/jupyterbook/lib/python3.10/asyncio/base_events.py", line 649, in run_until_complete
    return future.result()
  File "/opt/anaconda3/envs/jupyterbook/lib/python3.10/site-packages/nbclient/client.py", line 663, in async_execute
    await self.async_execute_cell(
  File "/opt/anaconda3/envs/jupyterbook/lib/python3.10/site-packages/nbclient/client.py", line 965, in async_execute_cell
    await self._check_raise_for_error(cell, cell_index, exec_reply)
  File "/opt/anaconda3/envs/jupyterbook/lib/python3.10/site-packages/nbclient/client.py", line 862, in _check_raise_for_error
    raise CellExecutionError.from_cell_and_msg(cell, exec_reply_content)
nbclient.exceptions.CellExecutionError: An error occurred while executing the following cell:
------------------
import numpy as np
import matplotlib.pyplot as plt
import sys, os
import time

os.chdir("/content/drive/MyDrive/Colab Notebooks/deep-learning-from-scratch")
from common.layers import *
from common.gradient import numerical_gradient
from collections import OrderedDict
import torch
from dataset.mnist import load_mnist
from ch05.two_layer_net import TwoLayerNet
from common.functions import softmax # ソフトマックス関数:バッチ対応版
from common.functions import cross_entropy_error # 交差エントロピー誤差:4.2.4項
------------------

[0;31m---------------------------------------------------------------------------[0m
[0;31mFileNotFoundError[0m                         Traceback (most recent call last)
Cell [0;32mIn[1], line 6[0m
[1;32m      3[0m [38;5;28;01mimport[39;00m [38;5;21;01msys[39;00m[38;5;241m,[39m [38;5;21;01mos[39;00m
[1;32m      4[0m [38;5;28;01mimport[39;00m [38;5;21;01mtime[39;00m
[0;32m----> 6[0m [43mos[49m[38;5;241;43m.[39;49m[43mchdir[49m[43m([49m[38;5;124;43m"[39;49m[38;5;124;43m/content/drive/MyDrive/Colab Notebooks/deep-learning-from-scratch[39;49m[38;5;124;43m"[39;49m[43m)[49m
[1;32m      7[0m [38;5;28;01mfrom[39;00m [38;5;21;01mcommon[39;00m[38;5;21;01m.[39;00m[38;5;21;01mlayers[39;00m [38;5;28;01mimport[39;00m [38;5;241m*[39m
[1;32m      8[0m [38;5;28;01mfrom[39;00m [38;5;21;01mcommon[39;00m[38;5;21;01m.[39;00m[38;5;21;01mgradient[39;00m [38;5;28;01mimport[39;00m numerical_gradient

[0;31mFileNotFoundError[0m: [Errno 2] No such file or directory: '/content/drive/MyDrive/Colab Notebooks/deep-learning-from-scratch'
FileNotFoundError: [Errno 2] No such file or directory: '/content/drive/MyDrive/Colab Notebooks/deep-learning-from-scratch'

