Traceback (most recent call last):
  File "/opt/anaconda3/envs/jupyterbook/lib/python3.10/site-packages/jupyter_cache/executors/utils.py", line 51, in single_nb_execution
    executenb(
  File "/opt/anaconda3/envs/jupyterbook/lib/python3.10/site-packages/nbclient/client.py", line 1204, in execute
    return NotebookClient(nb=nb, resources=resources, km=km, **kwargs).execute()
  File "/opt/anaconda3/envs/jupyterbook/lib/python3.10/site-packages/nbclient/util.py", line 84, in wrapped
    return just_run(coro(*args, **kwargs))
  File "/opt/anaconda3/envs/jupyterbook/lib/python3.10/site-packages/nbclient/util.py", line 62, in just_run
    return loop.run_until_complete(coro)
  File "/opt/anaconda3/envs/jupyterbook/lib/python3.10/asyncio/base_events.py", line 649, in run_until_complete
    return future.result()
  File "/opt/anaconda3/envs/jupyterbook/lib/python3.10/site-packages/nbclient/client.py", line 663, in async_execute
    await self.async_execute_cell(
  File "/opt/anaconda3/envs/jupyterbook/lib/python3.10/site-packages/nbclient/client.py", line 965, in async_execute_cell
    await self._check_raise_for_error(cell, cell_index, exec_reply)
  File "/opt/anaconda3/envs/jupyterbook/lib/python3.10/site-packages/nbclient/client.py", line 862, in _check_raise_for_error
    raise CellExecutionError.from_cell_and_msg(cell, exec_reply_content)
nbclient.exceptions.CellExecutionError: An error occurred while executing the following cell:
------------------
# Create a scatter plot with regression line using proplot
fig, ax = pplt.subplots()
ax.scatter(X_test, y_test, label='Actual')
ax.plot(X_test, y_predicted, c='red', label='Regression Line')

# Set plot labels and title
ax.set_xlabel('Petal Length (cm)')
ax.set_ylabel('Petal Width (cm)')

# Add legend
ax.legend()

# Show the plot
plt.show()
------------------

[0;31m---------------------------------------------------------------------------[0m
[0;31mNameError[0m                                 Traceback (most recent call last)
Cell [0;32mIn[12], line 14[0m
[1;32m     11[0m ax[38;5;241m.[39mlegend()
[1;32m     13[0m [38;5;66;03m# Show the plot[39;00m
[0;32m---> 14[0m [43mplt[49m[38;5;241m.[39mshow()

[0;31mNameError[0m: name 'plt' is not defined
NameError: name 'plt' is not defined

