Traceback (most recent call last):
  File "/Users/ryozawau/anaconda3/envs/jupyterbook/lib/python3.12/site-packages/jupyter_cache/executors/utils.py", line 58, in single_nb_execution
    executenb(
  File "/Users/ryozawau/anaconda3/envs/jupyterbook/lib/python3.12/site-packages/nbclient/client.py", line 1305, in execute
    return NotebookClient(nb=nb, resources=resources, km=km, **kwargs).execute()
           ^^^^^^^^^^^^^^^^^^^^^^^^^^^^^^^^^^^^^^^^^^^^^^^^^^^^^^^^^^^^^^^^^^^^^
  File "/Users/ryozawau/anaconda3/envs/jupyterbook/lib/python3.12/site-packages/jupyter_core/utils/__init__.py", line 165, in wrapped
    return loop.run_until_complete(inner)
           ^^^^^^^^^^^^^^^^^^^^^^^^^^^^^^
  File "/Users/ryozawau/anaconda3/envs/jupyterbook/lib/python3.12/asyncio/base_events.py", line 684, in run_until_complete
    return future.result()
           ^^^^^^^^^^^^^^^
  File "/Users/ryozawau/anaconda3/envs/jupyterbook/lib/python3.12/site-packages/nbclient/client.py", line 705, in async_execute
    await self.async_execute_cell(
  File "/Users/ryozawau/anaconda3/envs/jupyterbook/lib/python3.12/site-packages/nbclient/client.py", line 1058, in async_execute_cell
    await self._check_raise_for_error(cell, cell_index, exec_reply)
  File "/Users/ryozawau/anaconda3/envs/jupyterbook/lib/python3.12/site-packages/nbclient/client.py", line 914, in _check_raise_for_error
    raise CellExecutionError.from_cell_and_msg(cell, exec_reply_content)
nbclient.exceptions.CellExecutionError: An error occurred while executing the following cell:
------------------
import matplotlib.pyplot as plt
plt.rcParams['xtick.direction'] = "out"
plt.rcParams['ytick.direction'] = "in"

normal = np.random.normal(0, 1, 2000)
plt.hist(normal, bins=50, density=True, alpha=0.6, color='b')
plt.show()
------------------


[0;31m---------------------------------------------------------------------------[0m
[0;31mModuleNotFoundError[0m                       Traceback (most recent call last)
Cell [0;32mIn[15], line 1[0m
[0;32m----> 1[0m [38;5;28;01mimport[39;00m [38;5;21;01mmatplotlib[39;00m[38;5;21;01m.[39;00m[38;5;21;01mpyplot[39;00m [38;5;28;01mas[39;00m [38;5;21;01mplt[39;00m
[1;32m      2[0m plt[38;5;241m.[39mrcParams[[38;5;124m'[39m[38;5;124mxtick.direction[39m[38;5;124m'[39m] [38;5;241m=[39m [38;5;124m"[39m[38;5;124mout[39m[38;5;124m"[39m
[1;32m      3[0m plt[38;5;241m.[39mrcParams[[38;5;124m'[39m[38;5;124mytick.direction[39m[38;5;124m'[39m] [38;5;241m=[39m [38;5;124m"[39m[38;5;124min[39m[38;5;124m"[39m

[0;31mModuleNotFoundError[0m: No module named 'matplotlib'

