Traceback (most recent call last):
  File "/Users/ryozawau/anaconda3/envs/jupyterbook/lib/python3.12/site-packages/jupyter_cache/executors/utils.py", line 58, in single_nb_execution
    executenb(
  File "/Users/ryozawau/anaconda3/envs/jupyterbook/lib/python3.12/site-packages/nbclient/client.py", line 1305, in execute
    return NotebookClient(nb=nb, resources=resources, km=km, **kwargs).execute()
           ^^^^^^^^^^^^^^^^^^^^^^^^^^^^^^^^^^^^^^^^^^^^^^^^^^^^^^^^^^^^^^^^^^^^^
  File "/Users/ryozawau/anaconda3/envs/jupyterbook/lib/python3.12/site-packages/jupyter_core/utils/__init__.py", line 165, in wrapped
    return loop.run_until_complete(inner)
           ^^^^^^^^^^^^^^^^^^^^^^^^^^^^^^
  File "/Users/ryozawau/anaconda3/envs/jupyterbook/lib/python3.12/asyncio/base_events.py", line 684, in run_until_complete
    return future.result()
           ^^^^^^^^^^^^^^^
  File "/Users/ryozawau/anaconda3/envs/jupyterbook/lib/python3.12/site-packages/nbclient/client.py", line 705, in async_execute
    await self.async_execute_cell(
  File "/Users/ryozawau/anaconda3/envs/jupyterbook/lib/python3.12/site-packages/nbclient/client.py", line 1058, in async_execute_cell
    await self._check_raise_for_error(cell, cell_index, exec_reply)
  File "/Users/ryozawau/anaconda3/envs/jupyterbook/lib/python3.12/site-packages/nbclient/client.py", line 914, in _check_raise_for_error
    raise CellExecutionError.from_cell_and_msg(cell, exec_reply_content)
nbclient.exceptions.CellExecutionError: An error occurred while executing the following cell:
------------------
import proplot as pplt
fig, ax = pplt.subplots()

iris= datasets.load_iris()
X = iris.data # 特徴量データ


# Extract petal length and petal width
petal_length = X[:, 2]
petal_width = X[:, 3]

# Create a scatter plot using proplot

ax.scatter(petal_length, petal_width)
# Set plot labels and title
ax.set_xlabel('Petal Length (cm)')
ax.set_ylabel('Petal Width (cm)')
------------------


[0;31m---------------------------------------------------------------------------[0m
[0;31mModuleNotFoundError[0m                       Traceback (most recent call last)
Cell [0;32mIn[10], line 1[0m
[0;32m----> 1[0m [38;5;28;01mimport[39;00m [38;5;21;01mproplot[39;00m [38;5;28;01mas[39;00m [38;5;21;01mpplt[39;00m
[1;32m      2[0m fig, ax [38;5;241m=[39m pplt[38;5;241m.[39msubplots()
[1;32m      4[0m iris[38;5;241m=[39m datasets[38;5;241m.[39mload_iris()

[0;31mModuleNotFoundError[0m: No module named 'proplot'

