Traceback (most recent call last):
  File "/opt/anaconda3/envs/jupyterbook/lib/python3.10/site-packages/jupyter_cache/executors/utils.py", line 51, in single_nb_execution
    executenb(
  File "/opt/anaconda3/envs/jupyterbook/lib/python3.10/site-packages/nbclient/client.py", line 1204, in execute
    return NotebookClient(nb=nb, resources=resources, km=km, **kwargs).execute()
  File "/opt/anaconda3/envs/jupyterbook/lib/python3.10/site-packages/nbclient/util.py", line 84, in wrapped
    return just_run(coro(*args, **kwargs))
  File "/opt/anaconda3/envs/jupyterbook/lib/python3.10/site-packages/nbclient/util.py", line 62, in just_run
    return loop.run_until_complete(coro)
  File "/opt/anaconda3/envs/jupyterbook/lib/python3.10/asyncio/base_events.py", line 649, in run_until_complete
    return future.result()
  File "/opt/anaconda3/envs/jupyterbook/lib/python3.10/site-packages/nbclient/client.py", line 663, in async_execute
    await self.async_execute_cell(
  File "/opt/anaconda3/envs/jupyterbook/lib/python3.10/site-packages/nbclient/client.py", line 965, in async_execute_cell
    await self._check_raise_for_error(cell, cell_index, exec_reply)
  File "/opt/anaconda3/envs/jupyterbook/lib/python3.10/site-packages/nbclient/client.py", line 862, in _check_raise_for_error
    raise CellExecutionError.from_cell_and_msg(cell, exec_reply_content)
nbclient.exceptions.CellExecutionError: An error occurred while executing the following cell:
------------------
from sklearn.linear_model import LinearRegression
from sklearn.metrics import mean_squared_error

iris = load_iris()
X = iris.data[:, 2:3]  # Petal length as input feature
y = iris.data[:, 3]  # Petal width as target variable


# 訓練データとテストデータに分割
X_train, X_test, y_train, y_test = train_test_split(X, y, test_size=0.3, random_state=1)

model=LinearRegression() # 線形回帰モデル
model.fit(X_train,y_train) # モデルを訓練データに適合
y_predicted=model.predict(X_test) # テストデータで予測
mean_squared_error(y_test,y_predicted) # 予測精度（平均二乗誤差）の評価
------------------

[0;31m---------------------------------------------------------------------------[0m
[0;31mNameError[0m                                 Traceback (most recent call last)
Cell [0;32mIn[13], line 4[0m
[1;32m      1[0m [38;5;28;01mfrom[39;00m [38;5;21;01msklearn[39;00m[38;5;21;01m.[39;00m[38;5;21;01mlinear_model[39;00m [38;5;28;01mimport[39;00m LinearRegression
[1;32m      2[0m [38;5;28;01mfrom[39;00m [38;5;21;01msklearn[39;00m[38;5;21;01m.[39;00m[38;5;21;01mmetrics[39;00m [38;5;28;01mimport[39;00m mean_squared_error
[0;32m----> 4[0m iris [38;5;241m=[39m [43mload_iris[49m()
[1;32m      5[0m X [38;5;241m=[39m iris[38;5;241m.[39mdata[:, [38;5;241m2[39m:[38;5;241m3[39m]  [38;5;66;03m# Petal length as input feature[39;00m
[1;32m      6[0m y [38;5;241m=[39m iris[38;5;241m.[39mdata[:, [38;5;241m3[39m]  [38;5;66;03m# Petal width as target variable[39;00m

[0;31mNameError[0m: name 'load_iris' is not defined
NameError: name 'load_iris' is not defined

